Workbook

Sheet cars
A1: lp. | B1: Prędkość (m/s) | C1: Droga hamowania(ft)
A2: 1 | B2: 4 | C2: 2 | G2: Źródło | H2: Ezekiel, M. (1930) Methods of Correlation Analysis. Wiley.
A3: 2 | B3: 4 | C3: 10
A4: 3 | B4: 7 | C4: 4
A5: 4 | B5: 7 | C5: 22
A6: 5 | B6: 8 | C6: 16
A7: 6 | B7: 9 | C7: 10
A8: 7 | B8: 10 | C8: 18
A9: 8 | B9: 10 | C9: 26
A10: 9 | B10: 10 | C10: 34
A11: 10 | B11: 11 | C11: 17
A12: 11 | B12: 11 | C12: 28 | G12: wsp. Korelacji | H12: =CORREL(B2:B51,C2:C51) -> 0.8068949
A13: 12 | B13: 12 | C13: 14 | G13: silna korelacja
A14: 13 | B14: 12 | C14: 20 | G14: Pomiędzy prędkością samochodu a drogą hamowania istnieje silna, dodatnia zależność liniowa. Oznacza to, że im wyższa jest prędkość pojazdu, tym dłuższa jest wymagana droga hamowania.
A15: 14 | B15: 12 | C15: 24
A16: 15 | B16: 12 | C16: 28
A17: 16 | B17: 13 | C17: 26
A18: 17 | B18: 13 | C18: 34
A19: 18 | B19: 13 | C19: 34
A20: 19 | B20: 13 | C20: 46
A21: 20 | B21: 14 | C21: 26
A22: 21 | B22: 14 | C22: 36
A23: 22 | B23: 14 | C23: 60
A24: 23 | B24: 14 | C24: 80
A25: 24 | B25: 15 | C25: 20
A26: 25 | B26: 15 | C26: 26
... A51: 50 | B51: 25 | C51: 85

Sheet Dane ilościowe dyskretne
A1: Lp | B1: Opinia najlepszy gatunek filmowy
A2: 1 | B2: Komedia | E2: Gatunek | F2: Ilość głosów | G2: Procent
A3: 2 | B3: Thriller | E3: Komedia | F3: =COUNTIF($B$2:$B$61,E3) -> 8 | G3: =F3/$F$9 -> 0.13333333
A4: 3 | B4: Dramat | E4: Thriller | F4: =COUNTIF($B$2:$B$61,E4) -> 17 | G4: =F4/$F$9 -> 0.28333333
A5: 4 | B5: Dokument | E5: Dramat | F5: =COUNTIF($B$2:$B$61,E5) -> 14 | G5: =F5/$F$9 -> 0.23333333
A6: 5 | B6: Fantasy | E6: Dokument | F6: =COUNTIF($B$2:$B$61,E6) -> 11 | G6: =F6/$F$9 -> 0.18333333
A7: 6 | B7: Dokument | E7: Fantasy | F7: =COUNTIF($B$2:$B$61,E7) -> 10 | G7: =F7/$F$9 -> 0.16666667
A8: 7 | B8: Dramat
A9: 8 | B9: Thriller | E9: Suma | F9: =SUM(F3:F7) -> 60
A10: 9 | B10: Dokument
A11: 10 | B11: Komedia
A12: 11 | B12: Fantasy
A13: 12 | B13: Dokument
A14: 13 | B14: Dramat
A15: 14 | B15: Dokument
A16: 15 | B16: Thriller
A17: 16 | B17: Dramat
A18: 17 | B18: Dokument
A19: 18 | B19: Thriller
A20: 19 | B20: Fantasy
A21: 20 | B21: Thriller
... A61: 60 | B61: Komedia

Sheet Dane ilościowe - sz.czasowy
A1: Kusy waluty Euro 2025
A2: https://nbp.pl/statystyka-i-sprawozdawczosc/kursy/archiwum-tabela-a-csv-xls/
C7: data | D7: 1 EUR
D8: euro
C9: 45659 | D9: 4.2668
C10: 45660 | D10: 4.2718
C11: 45664 | D11: 4.2515
C12: 45665 | D12: 4.2656
C13: 45666 | D13: 4.2794
C14: 45667 | D14: 4.2657
C15: 45670 | D15: 4.2715
C16: 45671 | D16: 4.2737
C17: 45672 | D17: 4.2611
C18: 45673 | D18: 4.262
C19: 45674 | D19: 4.2691
C20: 45677 | D20: 4.2587
... C244: 45996 | D244: 4.2321

Sheet Dane ilościowe - sz. przedziało
A1: Kusy waluty Euro 2025
A2: https://nbp.pl/statystyka-i-sprawozdawczosc/kursy/archiwum-tabela-a-csv-xls/
C7: data | D7: 1 EUR
A8: Lp. | D8: euro
A9: 1 | B9: styczeń | C9: 45659 | D9: 4.2668 | G9: Szereg rozdzielczy przedziałowy
A10: 2 | C10: 45660 | D10: 4.2718
A11: 3 | C11: 45664 | D11: 4.2515
A12: 4 | C12: 45665 | D12: 4.2656 | G12: Liczba przedziałów | L12: =SQRT(D247) -> 15.362291 | M12: przyjmujemy | N12: 16
A13: 5 | C13: 45666 | D13: 4.2794 | G13: Rozpiętość przedziału(stała we wszystkich przedziałach) | L13: =(D249-D248)/N12 -> 0.0105875
A14: 6 | C14: 45667 | D14: 4.2657
A15: 7 | C15: 45670 | D15: 4.2715
A16: 8 | C16: 45671 | D16: 4.2737
A17: 9 | C17: 45672 | D17: 4.2611
A18: 10 | C18: 45673 | D18: 4.262
A19: 11 | C19: 45674 | D19: 4.2691 | H19: przedzialy | I19: lewy koniec | J19: prawy koniec | L19: częstość | M19: częstość skumulowana | N19: względna częstość skumulowana
A20: 12 | C20: 45677 | D20: 4.2587 | G20: 1 | H20: ="["&I20&";"&J20&"]" -> [4,1339;4,1444875] | I20: =D248 -> 4.1339 | J20: =I20+$L$13 -> 4.1444875 | L20: {=FREQUENCY($D$9:$D$244,$J$20:$J$34)} -> 3 | M20: =SUBTOTAL(9,L20) -> 3 | N20: =M20/$M$35 -> 0.012711864
A21: 13 | C21: 45678 | D21: 4.2554 | G21: 2 | H21: ="("&I21&";"&J21&"]" -> (4,1444875;4,155075] | I21: =J20 -> 4.1444875 | J21: =I21+$L$13 -> 4.155075 | L21: 1 | M21: =SUBTOTAL(9,$L$20:L21) -> 4 | N21: =M21/$M$35 -> 0.016949153
A22: 14 | C22: 45679 | D22: 4.2461 | G22: 3 | H22: ="("&I22&";"&J22&"]" -> (4,155075;4,1656625] | I22: =J21 -> 4.155075 | J22: =I22+$L$13 -> 4.1656625 | L22: 8 | M22: =SUBTOTAL(9,$L$20:L22) -> 12 | N22: =M22/$M$35 -> 0.050847458
A23: 15 | C23: 45680 | D23: 4.2182 | G23: 4 | H23: ="("&I23&";"&J23&"]" -> (4,1656625;4,17625] | I23: =J22 -> 4.1656625 | J23: =I23+$L$13 -> 4.17625 | L23: 6 | M23: =SUBTOTAL(9,$L$20:L23) -> 18 | N23: =M23/$M$35 -> 0.076271186
A24: 16 | C24: 45681 | D24: 4.21 | G24: 5 | H24: ="("&I24&";"&J24&"]" -> (4,17625;4,1868375] | I24: =J23 -> 4.17625 | J24: =I24+$L$13 -> 4.1868375 | L24: 13 | M24: =SUBTOTAL(9,$L$20:L24) -> 31 | N24: =M24/$M$35 -> 0.13135593
A25: 17 | C25: 45684 | D25: 4.2176 | G25: 6 | H25: ="("&I25&";"&J25&"]" -> (4,1868375;4,197425] | I25: =J24 -> 4.1868375 | J25: =I25+$L$13 -> 4.197425 | L25: 6 | M25: =SUBTOTAL(9,$L$20:L25) -> 37 | N25: =M25/$M$35 -> 0.15677966
A26: 18 | C26: 45685 | D26: 4.2092 | G26: 7 | H26: ="("&I26&";"&J26&"]" -> (4,197425;4,2080125] | I26: =J25 -> 4.197425 | J26: =I26+$L$13 -> 4.2080125 | L26: 7 | M26: =SUBTOTAL(9,$L$20:L26) -> 44 | N26: =M26/$M$35 -> 0.18644068
A27: 19 | C27: 45686 | D27: 4.2077 | G27: 8 | H27: ="("&I27&";"&J27&"]" -> (4,2080125;4,2186] | I27: =J26 -> 4.2080125 | J27: =I27+$L$13 -> 4.2186 | L27: 5 | M27: =SUBTOTAL(9,$L$20:L27) -> 49 | N27: =M27/$M$35 -> 0.20762712
A28: 20 | C28: 45687 | D28: 4.2039 | G28: 9 | H28: ="("&I28&";"&J28&"]" -> (4,2186;4,2291875] | I28: =J27 -> 4.2186 | J28: =I28+$L$13 -> 4.2291875 | L28: 6 | M28: =SUBTOTAL(9,$L$20:L28) -> 55 | N28: =M28/$M$35 -> 0.23305085
A29: 21 | C29: 45688 | D29: 4.213 | G29: 10 | H29: ="("&I29&";"&J29&"]" -> (4,2291875;4,239775] | I29: =J28 -> 4.2291875 | J29: =I29+$L$13 -> 4.239775 | L29: 25 | M29: =SUBTOTAL(9,$L$20:L29) -> 80 | N29: =M29/$M$35 -> 0.33898305
A30: 22 | B30: luty | C30: 45691 | D30: 4.2305 | G30: 11 | H30: ="("&I30&";"&J30&"]" -> (4,239775;4,2503625] | I30: =J29 -> 4.239775 | J30: =I30+$L$13 -> 4.2503625 | L30: 27 | M30: =SUBTOTAL(9,$L$20:L30) -> 107 | N30: =M30/$M$35 -> 0.45338983
A31: 23 | C31: 45692 | D31: 4.2249 | G31: 12 | H31: ="("&I31&";"&J31&"]" -> (4,2503625;4,26095] | I31: =J30 -> 4.2503625 | J31: =I31+$L$13 -> 4.26095 | L31: 54 | M31: =SUBTOTAL(9,$L$20:L31) -> 161 | N31: =M31/$M$35 -> 0.68220339
A32: 24 | C32: 45693 | D32: 4.2059 | G32: 13 | H32: ="("&I32&";"&J32&"]" -> (4,26095;4,2715375] | I32: =J31 -> 4.26095 | J32: =I32+$L$13 -> 4.2715375 | L32: 38 | M32: =SUBTOTAL(9,$L$20:L32) -> 199 | N32: =M32/$M$35 -> 0.84322034
A33: 25 | C33: 45694 | D33: 4.2073 | G33: 14 | H33: ="("&I33&";"&J33&"]" -> (4,2715375;4,282125] | I33: =J32 -> 4.2715375 | J33: =I33+$L$13 -> 4.282125 | L33: 29 | M33: =SUBTOTAL(9,$L$20:L33) -> 228 | N33: =M33/$M$35 -> 0.96610169
A34: 26 | C34: 45695 | D34: 4.1898 | G34: 15 | H34: ="("&I34&";"&J34&"]" -> (4,282125;4,2927125] | I34: =J33 -> 4.282125 | J34: =I34+$L$13 -> 4.2927125 | L34: 4 | M34: =SUBTOTAL(9,$L$20:L34) -> 232 | N34: =M34/$M$35 -> 0.98305085
A35: 27 | C35: 45698 | D35: 4.1872 | G35: 16 | H35: ="("&I35&";"&J35&"]" -> (4,2927125;4,3033] | I35: =J34 -> 4.2927125 | J35: =I35+$L$13 -> 4.3033 | L35: 4 | M35: =SUBTOTAL(9,$L$20:L35) -> 236 | N35: =M35/$M$35 -> 1
A36: 28 | C36: 45699 | D36: 4.1783
A37: 29 | C37: 45700 | D37: 4.1721
A38: 30 | C38: 45701 | D38: 4.1652
A39: 31 | C39: 45702 | D39: 4.1632
A40: 32 | C40: 45705 | D40: 4.1635
A41: 33 | C41: 45706 | D41: 4.1574
A42: 34 | C42: 45707 | D42: 4.1582
A43: 35 | C43: 45708 | D43: 4.1723
A44: 36 | C44: 45709 | D44: 4.1705
...

Sheet Skrzynka wąsy
E8: data | F8: 1 EUR
C9: Lp. | F9: euro
C10: 1 | D10: styczeń | E10: 45659 | F10: 4.2668
C11: 2 | E11: 45660 | F11: 4.2718
C12: 3 | E12: 45664 | F12: 4.2515
C13: 4 | E13: 45665 | F13: 4.2656
C14: 5 | E14: 45666 | F14: 4.2794
C15: 6 | E15: 45667 | F15: 4.2657
C16: 7 | E16: 45670 | F16: 4.2715
C17: 8 | E17: 45671 | F17: 4.2737
C18: 9 | E18: 45672 | F18: 4.2611
C19: 10 | E19: 45673 | F19: 4.262
C20: 11 | E20: 45674 | F20: 4.2691
C21: 12 | E21: 45677 | F21: 4.2587
C22: 13 | E22: 45678 | F22: 4.2554
... C30: 21 | E30: 45688 | F30: 4.213
C31: 22 | D31: luty | E31: 45691 | F31: 4.2305
C32: 23 | E32: 45692 | F32: 4.2249
C33: 24 | E33: 45693 | F33: 4.2059
C34: 25 | E34: 45694 | F34: 4.2073
C35: 26 | E35: 45695 | F35: 4.1898
C36: 27 | E36: 45698 | F36: 4.1872
C37: 28 | E37: 45699 | F37: 4.1783
C38: 29 | E38: 45700 | F38: 4.1721
C39: 30 | E39: 45701 | F39: 4.1652
C40: 31 | E40: 45702 | F40: 4.1632
C41: 32 | E41: 45705 | F41: 4.1635
C42: 33 | E42: 45706 | F42: 4.1574
C43: 34 | E43: 45707 | F43: 4.1582
... C46: 37 | E46: 45712 | F46: 4.1609
C47: 38 | E47: 45713 | F47: 4.1339 | I47: Szereg rozdzielczy został poprawnie utworzony na podstawie 236 notowań kursu EURO, przyjęto 16 przedziałów, a błędy w kolumnach procentowych zostały skorygowane (suma częstości względnych wynosi 100,0%
C48: 39 | E48: 45714 | F48: 4.1394 | I48: Mediana kursu (linia wewnątrz ramki) znajduje się w pobliżu 4,25 PLN. Oznacza to, że ok 50% wszystkich obserwacji kursu EUR0 w PLN w badanym okresie było niższych od tej wartości, a pozostałe 50% wyższych.
C49: 40 | E49: 45715 | F49: 4.1371 | I49: Środkowe 50% notowań charakteryzuje się niewielkim zróżnicowaniem i jest mocno skupione w tym wąskim zakresie
C50: 41 | E50: 45716 | F50: 4.1575 | I50: Rozkład notowań jest asymetryczny (ukośny) z tendencją lewostronną (ujemną). Oznacza to, że notowania są skupione na wyższych kursach, a rzadsze, niskie kursy są bardziej rozproszone i tworzą kropki w lewo.
C51: 42 | D51: marzec | E51: 45719 | F51: 4.1827 | I51: Istnieją też notowania minimelna około 4,20, które znacząco odbiegają.
C52: 43 | E52: 45720 | F52: 4.1568
C53: 44 | E53: 45721 | F53: 4.1545
C54: 45 | E54: 45722 | F54: 4.1766
C55: 46 | E55: 45723 | F55: 4.176
C56: 47 | E56: 45726 | F56: 4.1857
...

Sheet Histogram
E8: data | F8: 1 EUR
C9: Lp. | F9: euro
C10: 1 | D10: styczeń | E10: 45659 | F10: 4.2668
C11: 2 | E11: 45660 | F11: 4.2718
C12: 3 | E12: 45664 | F12: 4.2515
C13: 4 | E13: 45665 | F13: 4.2656
C14: 5 | E14: 45666 | F14: 4.2794
C15: 6 | E15: 45667 | F15: 4.2657
C16: 7 | E16: 45670 | F16: 4.2715
C17: 8 | E17: 45671 | F17: 4.2737
C18: 9 | E18: 45672 | F18: 4.2611
C19: 10 | E19: 45673 | F19: 4.262
C20: 11 | E20: 45674 | F20: 4.2691
C21: 12 | E21: 45677 | F21: 4.2587
C22: 13 | E22: 45678 | F22: 4.2554
... C30: 21 | E30: 45688 | F30: 4.213
C31: 22 | D31: luty | E31: 45691 | F31: 4.2305
C32: 23 | E32: 45692 | F32: 4.2249
C33: 24 | E33: 45693 | F33: 4.2059
C34: 25 | E34: 45694 | F34: 4.2073
C35: 26 | E35: 45695 | F35: 4.1898
C36: 27 | E36: 45698 | F36: 4.1872
C37: 28 | E37: 45699 | F37: 4.1783
C38: 29 | E38: 45700 | F38: 4.1721
C39: 30 | E39: 45701 | F39: 4.1652
C40: 31 | E40: 45702 | F40: 4.1632
C41: 32 | E41: 45705 | F41: 4.1635
C42: 33 | E42: 45706 | F42: 4.1574
C43: 34 | E43: 45707 | F43: 4.1582
... C50: 41 | E50: 45716 | F50: 4.1575
C51: 42 | D51: marzec | E51: 45719 | F51: 4.1827
C52: 43 | E52: 45720 | F52: 4.1568 | R52: zbior danych koszyk | S52: Częstość
C53: 44 | E53: 45721 | F53: 4.1545 | Q53: 1 | R53: ='Dane ilościowe - sz. przedziało'!I20 -> 4.1339 | S53: ='Dane ilościowe - sz. przedziało'!L20 -> 3 | T53: ='Dane ilościowe - sz. przedziało'!N20 -> 0.012711864
C54: 45 | E54: 45722 | F54: 4.1766 | Q54: 2 | R54: ='Dane ilościowe - sz. przedziało'!I21 -> 4.1444875 | S54: ='Dane ilościowe - sz. przedziało'!L21 -> 1 | T54: ='Dane ilościowe - sz. przedziało'!N21 -> 0.016949153
C55: 46 | E55: 45723 | F55: 4.176 | Q55: 3 | R55: ='Dane ilościowe - sz. przedziało'!I22 -> 4.155075 | S55: ='Dane ilościowe - sz. przedziało'!L22 -> 8 | T55: ='Dane ilościowe - sz. przedziało'!N22 -> 0.050847458
C56: 47 | E56: 45726 | F56: 4.1857 | Q56: 4 | R56: ='Dane ilościowe - sz. przedziało'!I23 -> 4.1656625 | S56: ='Dane ilościowe - sz. przedziało'!L23 -> 6 | T56: ='Dane ilościowe - sz. przedziało'!N23 -> 0.076271186
C57: 48 | E57: 45727 | F57: 4.1977 | I57: ilosc obserwacji | N57: ='Dane ilościowe - sz. przedziało'!D247 -> 236 | Q57: 5 | R57: ='Dane ilościowe - sz. przedziało'!I24 -> 4.17625 | S57: ='Dane ilościowe - sz. przedziało'!L24 -> 13 | T57: ='Dane ilościowe - sz. przedziało'!N24 -> 0.13135593
C58: 49 | E58: 45728 | F58: 4.2017 | I58: Liczba przedziałów | N58: ='Dane ilościowe - sz. przedziało'!L12 -> 15.362291 | O58: przyjmujemy | P58: ='Dane ilościowe - sz. przedziało'!N12 -> 16 | Q58: 6 | R58: ='Dane ilościowe - sz. przedziało'!I25 -> 4.1868375 | S58: ='Dane ilościowe - sz. przedziało'!L25 -> 6 | T58: ='Dane ilościowe - sz. przedziało'!N25 -> 0.15677966
C59: 50 | E59: 45729 | F59: 4.196 | I59: Rozpiętość przedziału(stała we wszystkich przedziałach) | N59: ='Dane ilościowe - sz. przedziało'!L13 -> 0.0105875 | Q59: 7 | R59: ='Dane ilościowe - sz. przedziało'!I26 -> 4.197425 | S59: ='Dane ilościowe - sz. przedziało'!L26 -> 7 | T59: ='Dane ilościowe - sz. przedziało'!N26 -> 0.18644068
C60: 51 | E60: 45730 | F60: 4.179 | I60: min | N60: ='Dane ilościowe - sz. przedziało'!D248 -> 4.1339 | Q60: 8 | R60: ='Dane ilościowe - sz. przedziało'!I27 -> 4.2080125 | S60: ='Dane ilościowe - sz. przedziało'!L27 -> 5 | T60: ='Dane ilościowe - sz. przedziało'!N27 -> 0.20762712
...
